[20/Feb/2020 11:13:43] "GET /api/announcement?offset=0&limit=10 HTTP/1.1" 200 84
[20/Feb/2020 11:13:43] "GET /api/website HTTP/1.1" 200 291
[2020-02-20 11:13:43] - [ERROR] - [root:156]  - column contest.assigned_lecture_id does not exist
LINE 1: ...ontest"."visible", "contest"."allowed_ip_ranges", "contest"....
                                                             ^
Traceback (most recent call last):
  File "/home/server/OJ/venv/lib/python3.7/site-packages/django/db/backends/utils.py", line 85, in _execute
    return self.cursor.execute(sql, params)
psycopg2.ProgrammingError: column contest.assigned_lecture_id does not exist
LINE 1: ...ontest"."visible", "contest"."allowed_ip_ranges", "contest"....
                                                             ^


The above exception was the direct cause of the following exception:

Traceback (most recent call last):
  File "/home/server/OJ/OnlineJudge/utils/api/api.py", line 149, in dispatch
    return super(APIView, self).dispatch(request, *args, **kwargs)
  File "/home/server/OJ/venv/lib/python3.7/site-packages/django/views/generic/base.py", line 88, in dispatch
    return handler(request, *args, **kwargs)
  File "/home/server/OJ/OnlineJudge/contest/views/oj.py", line 67, in get
    return self.success(self.paginate_data(request, contests, ContestSerializer))
  File "/home/server/OJ/OnlineJudge/utils/api/api.py", line 135, in paginate_data
    results = object_serializer(results, many=True).data
  File "/home/server/OJ/venv/lib/python3.7/site-packages/rest_framework/serializers.py", line 765, in data
    ret = super(ListSerializer, self).data
  File "/home/server/OJ/venv/lib/python3.7/site-packages/rest_framework/serializers.py", line 262, in data
    self._data = self.to_representation(self.instance)
  File "/home/server/OJ/venv/lib/python3.7/site-packages/rest_framework/serializers.py", line 683, in to_representation
    self.child.to_representation(item) for item in iterable
  File "/home/server/OJ/venv/lib/python3.7/site-packages/django/db/models/query.py", line 268, in __iter__
    self._fetch_all()
  File "/home/server/OJ/venv/lib/python3.7/site-packages/django/db/models/query.py", line 1186, in _fetch_all
    self._result_cache = list(self._iterable_class(self))
  File "/home/server/OJ/venv/lib/python3.7/site-packages/django/db/models/query.py", line 54, in __iter__
    results = compiler.execute_sql(chunked_fetch=self.chunked_fetch, chunk_size=self.chunk_size)
  File "/home/server/OJ/venv/lib/python3.7/site-packages/django/db/models/sql/compiler.py", line 1065, in execute_sql
    cursor.execute(sql, params)
  File "/home/server/OJ/venv/lib/python3.7/site-packages/django/db/backends/utils.py", line 100, in execute
    return super().execute(sql, params)
  File "/home/server/OJ/venv/lib/python3.7/site-packages/django/db/backends/utils.py", line 68, in execute
    return self._execute_with_wrappers(sql, params, many=False, executor=self._execute)
  File "/home/server/OJ/venv/lib/python3.7/site-packages/django/db/backends/utils.py", line 77, in _execute_with_wrappers
    return executor(sql, params, many, context)
  File "/home/server/OJ/venv/lib/python3.7/site-packages/django/db/backends/utils.py", line 85, in _execute
    return self.cursor.execute(sql, params)
  File "/home/server/OJ/venv/lib/python3.7/site-packages/django/db/utils.py", line 89, in __exit__
    raise dj_exc_value.with_traceback(traceback) from exc_value
  File "/home/server/OJ/venv/lib/python3.7/site-packages/django/db/backends/utils.py", line 85, in _execute
    return self.cursor.execute(sql, params)
django.db.utils.ProgrammingError: column contest.assigned_lecture_id does not exist
LINE 1: ...ontest"."visible", "contest"."allowed_ip_ranges", "contest"....
                                                             ^

[20/Feb/2020 11:13:43] "GET /api/profile HTTP/1.1" 200 999
[20/Feb/2020 11:13:43] "GET /api/contests?offset=0&limit=5&status=1 HTTP/1.1" 200 59
[20/Feb/2020 11:13:46] "GET /api/logout HTTP/1.1" 200 39
[2020-02-20 11:13:46] - [ERROR] - [root:156]  - column contest.assigned_lecture_id does not exist
LINE 1: ...ontest"."visible", "contest"."allowed_ip_ranges", "contest"....
                                                             ^
Traceback (most recent call last):
  File "/home/server/OJ/venv/lib/python3.7/site-packages/django/db/backends/utils.py", line 85, in _execute
    return self.cursor.execute(sql, params)
psycopg2.ProgrammingError: column contest.assigned_lecture_id does not exist
LINE 1: ...ontest"."visible", "contest"."allowed_ip_ranges", "contest"....
                                                             ^


The above exception was the direct cause of the following exception:

Traceback (most recent call last):
  File "/home/server/OJ/OnlineJudge/utils/api/api.py", line 149, in dispatch
    return super(APIView, self).dispatch(request, *args, **kwargs)
  File "/home/server/OJ/venv/lib/python3.7/site-packages/django/views/generic/base.py", line 88, in dispatch
    return handler(request, *args, **kwargs)
  File "/home/server/OJ/OnlineJudge/contest/views/oj.py", line 67, in get
    return self.success(self.paginate_data(request, contests, ContestSerializer))
  File "/home/server/OJ/OnlineJudge/utils/api/api.py", line 135, in paginate_data
    results = object_serializer(results, many=True).data
  File "/home/server/OJ/venv/lib/python3.7/site-packages/rest_framework/serializers.py", line 765, in data
    ret = super(ListSerializer, self).data
  File "/home/server/OJ/venv/lib/python3.7/site-packages/rest_framework/serializers.py", line 262, in data
    self._data = self.to_representation(self.instance)
  File "/home/server/OJ/venv/lib/python3.7/site-packages/rest_framework/serializers.py", line 683, in to_representation
    self.child.to_representation(item) for item in iterable
  File "/home/server/OJ/venv/lib/python3.7/site-packages/django/db/models/query.py", line 268, in __iter__
    self._fetch_all()
  File "/home/server/OJ/venv/lib/python3.7/site-packages/django/db/models/query.py", line 1186, in _fetch_all
    self._result_cache = list(self._iterable_class(self))
  File "/home/server/OJ/venv/lib/python3.7/site-packages/django/db/models/query.py", line 54, in __iter__
    results = compiler.execute_sql(chunked_fetch=self.chunked_fetch, chunk_size=self.chunk_size)
  File "/home/server/OJ/venv/lib/python3.7/site-packages/django/db/models/sql/compiler.py", line 1065, in execute_sql
    cursor.execute(sql, params)
  File "/home/server/OJ/venv/lib/python3.7/site-packages/django/db/backends/utils.py", line 100, in execute
    return super().execute(sql, params)
  File "/home/server/OJ/venv/lib/python3.7/site-packages/django/db/backends/utils.py", line 68, in execute
    return self._execute_with_wrappers(sql, params, many=False, executor=self._execute)
  File "/home/server/OJ/venv/lib/python3.7/site-packages/django/db/backends/utils.py", line 77, in _execute_with_wrappers
    return executor(sql, params, many, context)
  File "/home/server/OJ/venv/lib/python3.7/site-packages/django/db/backends/utils.py", line 85, in _execute
    return self.cursor.execute(sql, params)
  File "/home/server/OJ/venv/lib/python3.7/site-packages/django/db/utils.py", line 89, in __exit__
    raise dj_exc_value.with_traceback(traceback) from exc_value
  File "/home/server/OJ/venv/lib/python3.7/site-packages/django/db/backends/utils.py", line 85, in _execute
    return self.cursor.execute(sql, params)
django.db.utils.ProgrammingError: column contest.assigned_lecture_id does not exist
LINE 1: ...ontest"."visible", "contest"."allowed_ip_ranges", "contest"....
                                                             ^

[20/Feb/2020 11:13:46] "GET /api/contests?offset=0&limit=5&status=1 HTTP/1.1" 200 59
[20/Feb/2020 11:13:46] "GET /api/announcement?offset=0&limit=10 HTTP/1.1" 200 84
[20/Feb/2020 11:13:55] "POST /api/tfa_required HTTP/1.1" 200 66
[20/Feb/2020 11:13:57] "POST /api/tfa_required HTTP/1.1" 200 66
[20/Feb/2020 11:13:57] "POST /api/login HTTP/1.1" 200 46
[20/Feb/2020 11:13:57] "GET /api/profile HTTP/1.1" 200 999
Django VERSION (2, 1, 7, 'final', 0)
Performing system checks...

System check identified no issues (0 silenced).
February 20, 2020 - 11:13:29
Django version 2.1.7, using settings 'oj.settings'
Starting development server at http://127.0.0.1:8000/
Quit the server with CONTROL-C.
